Workbook

Sheet Dashboard
A1: SCHOOL DASHBOARD
A3: Select School: | B3: Wharton
A5: Full Name: | B5: =VLOOKUP(B3,_Lookup!A:B,2,FALSE())
A6: Rank: | B6: =VLOOKUP(B3,_Lookup!A:C,3,FALSE())
A7: Total Faculty: | B7: =VLOOKUP(B3,_Lookup!A:D,4,FALSE())
A8: OM & IS Depts: | B8: =VLOOKUP(B3,_Lookup!A:E,5,FALSE())
A9: Analytics Dept: | B9: =VLOOKUP(B3,_Lookup!A:F,6,FALSE())
A11: # | B11: Department | C11: Faculty
A12: =IFERROR(IF(VLOOKUP($B$3&"|"&1,_DeptLookup!A:C,3,FALSE())<>"",1,""),"") | B12: =IFERROR(VLOOKUP($B$3&"|"&1,_DeptLookup!A:C,3,FALSE()),"") | C12: =IF(IFERROR(VLOOKUP($B$3&"|"&1,_DeptLookup!A:C,3,FALSE()),"")="",NA(),VLOOKUP($B$3&"|"&1,_DeptLookup!A:D,4,FALSE()))
A13: =IFERROR(IF(VLOOKUP($B$3&"|"&2,_DeptLookup!A:C,3,FALSE())<>"",2,""),"") | B13: =IFERROR(VLOOKUP($B$3&"|"&2,_DeptLookup!A:C,3,FALSE()),"") | C13: =IF(IFERROR(VLOOKUP($B$3&"|"&2,_DeptLookup!A:C,3,FALSE()),"")="",NA(),VLOOKUP($B$3&"|"&2,_DeptLookup!A:D,4,FALSE()))
A14: =IFERROR(IF(VLOOKUP($B$3&"|"&3,_DeptLookup!A:C,3,FALSE())<>"",3,""),"") | B14: =IFERROR(VLOOKUP($B$3&"|"&3,_DeptLookup!A:C,3,FALSE()),"") | C14: =IF(IFERROR(VLOOKUP($B$3&"|"&3,_DeptLookup!A:C,3,FALSE()),"")="",NA(),VLOOKUP($B$3&"|"&3,_DeptLookup!A:D,4,FALSE()))
A15: =IFERROR(IF(VLOOKUP($B$3&"|"&4,_DeptLookup!A:C,3,FALSE())<>"",4,""),"") | B15: =IFERROR(VLOOKUP($B$3&"|"&4,_DeptLookup!A:C,3,FALSE()),"") | C15: =IF(IFERROR(VLOOKUP($B$3&"|"&4,_DeptLookup!A:C,3,FALSE()),"")="",NA(),VLOOKUP($B$3&"|"&4,_DeptLookup!A:D,4,FALSE()))
A16: =IFERROR(IF(VLOOKUP($B$3&"|"&5,_DeptLookup!A:C,3,FALSE())<>"",5,""),"") | B16: =IFERROR(VLOOKUP($B$3&"|"&5,_DeptLookup!A:C,3,FALSE()),"") | C16: =IF(IFERROR(VLOOKUP($B$3&"|"&5,_DeptLookup!A:C,3,FALSE()),"")="",NA(),VLOOKUP($B$3&"|"&5,_DeptLookup!A:D,4,FALSE()))
A17: =IFERROR(IF(VLOOKUP($B$3&"|"&6,_DeptLookup!A:C,3,FALSE())<>"",6,""),"") | B17: =IFERROR(VLOOKUP($B$3&"|"&6,_DeptLookup!A:C,3,FALSE()),"") | C17: =IF(IFERROR(VLOOKUP($B$3&"|"&6,_DeptLookup!A:C,3,FALSE()),"")="",NA(),VLOOKUP($B$3&"|"&6,_DeptLookup!A:D,4,FALSE()))
A18: =IFERROR(IF(VLOOKUP($B$3&"|"&7,_DeptLookup!A:C,3,FALSE())<>"",7,""),"") | B18: =IFERROR(VLOOKUP($B$3&"|"&7,_DeptLookup!A:C,3,FALSE()),"") | C18: =IF(IFERROR(VLOOKUP($B$3&"|"&7,_DeptLookup!A:C,3,FALSE()),"")="",NA(),VLOOKUP($B$3&"|"&7,_DeptLookup!A:D,4,FALSE()))
A19: =IFERROR(IF(VLOOKUP($B$3&"|"&8,_DeptLookup!A:C,3,FALSE())<>"",8,""),"") | B19: =IFERROR(VLOOKUP($B$3&"|"&8,_DeptLookup!A:C,3,FALSE()),"") | C19: =IF(IFERROR(VLOOKUP($B$3&"|"&8,_DeptLookup!A:C,3,FALSE()),"")="",NA(),VLOOKUP($B$3&"|"&8,_DeptLookup!A:D,4,FALSE()))
A20: =IFERROR(IF(VLOOKUP($B$3&"|"&9,_DeptLookup!A:C,3,FALSE())<>"",9,""),"") | B20: =IFERROR(VLOOKUP($B$3&"|"&9,_DeptLookup!A:C,3,FALSE()),"") | C20: =IF(IFERROR(VLOOKUP($B$3&"|"&9,_DeptLookup!A:C,3,FALSE()),"")="",NA(),VLOOKUP($B$3&"|"&9,_DeptLookup!A:D,4,FALSE()))
A21: =IFERROR(IF(VLOOKUP($B$3&"|"&10,_DeptLookup!A:C,3,FALSE())<>"",10,""),"") | B21: =IFERROR(VLOOKUP($B$3&"|"&10,_DeptLookup!A:C,3,FALSE()),"") | C21: =IF(IFERROR(VLOOKUP($B$3&"|"&10,_DeptLookup!A:C,3,FALSE()),"")="",NA(),VLOOKUP($B$3&"|"&10,_DeptLookup!A:D,4,FALSE()))
A22: =IFERROR(IF(VLOOKUP($B$3&"|"&11,_DeptLookup!A:C,3,FALSE())<>"",11,""),"") | B22: =IFERROR(VLOOKUP($B$3&"|"&11,_DeptLookup!A:C,3,FALSE()),"") | C22: =IF(IFERROR(VLOOKUP($B$3&"|"&11,_DeptLookup!A:C,3,FALSE()),"")="",NA(),VLOOKUP($B$3&"|"&11,_DeptLookup!A:D,4,FALSE()))

Sheet 1. School Overview
A1: Top 50 U.S. Business Schools — Faculty Composition (2025)
A2: T-T = tenure-track + tenured only; excludes lecturers, adjuncts, emeriti
A3: Rank | B3: School Full Name | C3: Short Name | D3: Location | E3: Type | F3: Departments | G3: Total T-T Faculty
A4: 1 | B4: University of Pennsylvania – Wharton School | C4: Wharton | D4: 246 | E4: Private | F4: 10 | G4: 246
A5: 2 | B5: Harvard University – Harvard Business School | C5: Harvard HBS | D5: 201 | E5: Private | F5: 10 | G5: 209
A6: 3 | B6: University of Chicago – Booth School of Business | C6: Chicago Booth | D6: 144 | E6: Private | F6: 11 | G6: 144
A7: 4 | B7: Northwestern University – Kellogg School of Management | C7: Kellogg | D7: 141 | E7: Private | F7: 7 | G7: 141
A8: 5 | B8: MIT – Sloan School of Management | C8: MIT Sloan | D8: 129 | E8: Private | F8: 11 | G8: 129
A9: 6 | B9: Stanford University – Graduate School of Business | C9: Stanford GSB | D9: 122 | E9: Private | F9: 7 | G9: 122
A10: 7 | B10: Columbia University – Columbia Business School | C10: Columbia CBS | D10: 123 | E10: Private | F10: 6 | G10: 123
A11: 8 | B11: New York University – Stern School of Business | C11: NYU Stern | D11: 170 | E11: Private | F11: 6 | G11: 125
A12: 9 | B12: Dartmouth College – Tuck School of Business | C12: Dartmouth Tuck | D12: 55 | E12: Private | F12: 7 | G12: 34
A13: 10 | B13: Yale University – Yale School of Management | C13: Yale SOM | D13: 110 | E13: Private | F13: 7 | G13: 40
A14: 11 | B14: UC Berkeley – Haas School of Business | C14: Berkeley Haas | D14: 84 | E14: Public | F14: 6 | G14: 84
A15: 12 | B15: University of Virginia – Darden School | C15: UVA Darden | D15: 89 | E15: Public | F15: 6 | G15: 50
... A36: 33 | B36: Purdue University – Krannert School of Management | C36: Purdue Krannert | D36: 104 | E36: Public | F36: 8 | G36: 79
A37: 34 | B37: Arizona State University – Carey School of Business | C37: ASU Carey | D37: Tempe, AZ | E37: Public | F37: 7 | G37: 44
A38: 35 | B38: University of Wisconsin – School of Business | C38: Wisconsin SoB | D38: 92 | E38: Public | F38: 7 | G38: 42
A39: 36 | B39: University of Maryland – Smith School of Business | C39: Maryland Smith | D39: 89 | E39: Public | F39: 6 | G39: 135
A40: 37 | B40: Boston University – Questrom School of Business | C40: BU Questrom | D40: 86 | E40: Private | F40: 8 | G40: 76
A41: 38 | B41: University of Florida – Warrington College | C41: UF Warrington | D41: 50 | E41: Public | F41: 5 | G41: 38
A42: 39 | B42: Southern Methodist Univ. – Cox School of Business | C42: SMU Cox | D42: 59 | E42: Private | F42: 6 | G42: 37
A43: 40 | B43: University of Washington – Foster School of Business | C43: UW Foster | D43: 95 | E43: Public | F43: 5 | G43: 48
A44: 41 | B44: University of Pittsburgh – Katz Graduate School | C44: Pitt Katz | D44: 59 | E44: Public | F44: 7 | G44: 51
A45: 42 | B45: Northeastern – DAmore-McKim School of Business | C45: NEU DAmore-McKim | D45: Boston, MA | E45: Private | F45: 7 | G45: 46
A46: 43 | B46: Tulane University – Freeman School of Business | C46: Tulane Freeman | D46: 57 | E46: Private | F46: 4 | G46: 50
A47: 44 | B47: University of Iowa – Tippie College of Business | C47: Iowa Tippie | D47: Iowa City, IA | E47: Public | F47: 6 | G47: 43
A48: 45 | B48: George Washington Univ. – School of Business | C48: GWU GWSB | D48: Washington, DC | E48: Private | F48: 8 | G48: 83
A49: 46 | B49: Brigham Young Univ. – Marriott School of Business | C49: BYU Marriott | D49: 123 | E49: Private | F49: 8 | G49: 62
A50: 47 | B50: Univ. of Rochester – Simon Business School | C50: Rochester Simon | D50: Rochester, NY | E50: Private | F50: 5 | G50: 43
A51: 48 | B51: Wake Forest Univ. – School of Business | C51: Wake Forest SoB | D51: Winston-Salem, NC | E51: Private | F51: 4 | G51: 50
A52: 49 | B52: Temple University – Fox School of Business | C52: Temple Fox | D52: Philadelphia, PA | E52: Public | F52: 9 | G52: 79
A53: 50 | B53: University of Miami – Miami Herbert Business School | C53: Miami Herbert | D53: Coral Gables, FL | E53: Private | F53: 8 | G53: 61
B54: TOTALS / AVERAGES | F54: =SUM(F4:F53) | G54: =SUM(G4:G53)
B55: AVERAGE PER SCHOOL | F55: =AVERAGE(F4:F53) | G55: =AVERAGE(G4:G53)

Sheet 2. Departments by School
A1: Top 50 U.S. Business Schools — Departments & Academic Units | G1: Department URL
A2: 1 | B2: Wharton | C2: Accounting | D2: Financial reporting, auditing, and tax research | E2: 4 | F2: 20 | G2: https://accounting.wharton.upenn.edu/faculty/
A3: 1 | B3: Wharton | C3: Business Economics & Public Policy | D3: Applied microeconomics, regulation, and public policy | E3: 4 | F3: 19 | G3: https://bepp.wharton.upenn.edu/faculty/
A4: 1 | B4: Wharton | C4: Finance | D4: Corporate finance, asset pricing, and financial intermediation | E4: 4 | F4: 39 | G4: https://fnce.wharton.upenn.edu/faculty/
A5: 1 | B5: Wharton | C5: Legal Studies & Business Ethics | D5: Business law, ethics, and corporate governance | E5: 4 | F5: 20 | G5: https://lgst.wharton.upenn.edu/faculty/
A6: 1 | B6: Wharton | C6: Management | D6: Organizational behavior, strategic management, and entrepreneurship | E6: 4 | F6: 47 | G6: https://mgmt.wharton.upenn.edu/faculty/
A7: 1 | B7: Wharton | C7: Marketing | D7: Consumer behavior, quantitative marketing, and digital marketing | E7: 4 | F7: 27 | G7: https://marketing.wharton.upenn.edu/faculty/
A8: 1 | B8: Wharton | C8: Operations, Information and Decisions (OID) | D8: Operations management, information systems, and decision sciences | E8: 4 | F8: 30 | G8: https://oid.wharton.upenn.edu/
A9: 1 | B9: Wharton | C9: Real Estate | D9: Real estate finance, urban economics, and housing markets | E9: 4 | F9: 10 | G9: https://real-estate.wharton.upenn.edu/faculty/
A10: 1 | B10: Wharton | C10: Statistics and Data Science | D10: Statistical methodology, machine learning, and causal inference | E10: 4 | F10: 23 | G10: https://statistics.wharton.upenn.edu/
A11: 1 | B11: Wharton | C11: Health Care Management | D11: Health care delivery, policy, and management innovation | E11: 4 | F11: 10 | G11: https://hcmg.wharton.upenn.edu/faculty/
A12: 2 | B12: Harvard HBS | C12: Accounting & Management | D12: Financial reporting, management control, and accounting research | E12: 4 | F12: 13 | G12: https://www.hbs.edu/faculty/units/am/Pages/faculty.aspx
A13: 2 | B13: Harvard HBS | C13: Business, Government & the International Economy | D13: Political economy, international trade, and economic policy | E13: 4 | F13: 18 | G13: https://www.hbs.edu/faculty/units/bgie/Pages/faculty.aspx
... A339: 50 | B339: Miami Herbert | C339: Marketing | D339: Generating insights into consumer behavior, market dynamics, and marketing strategy through innovative research methodologies. | E339: 4 | F339: 8 | G339: https://herbert.miami.edu/faculty-research/academic-departments/
E340: =SUM(E4:E321) | F340: =SUM(F4:F321)
A367: 4 | B367: Kellogg | C367: MEDS (Analytics & Decision Sciences) | D367: Analytics / Data Science | E367: 4 | F367: 20 | G367: https://www.kellogg.northwestern.edu/faculty/academics/managerial-economics-decision-sciences.aspx
A368: 12 | B368: UVA Darden | C368: Data Analytics & Decision Sciences (DADS) | D368: Analytics / Data Science | E368: 4 | F368: 10 | G368: https://www.darden.virginia.edu/faculty-research/academic-areas/data-analytics-decision-sciences
A369: 22 | B369: Georgetown McDonough | C369: Operations & Analytics (OPAN) | D369: Analytics / Data Science | E369: 4 | F369: 16
A370: 23 | B370: Indiana Kelley | C370: Operations & Decision Technologies (ODT) | D370: Analytics / Data Science | E370: 4 | F370: 37
A371: 41 | B371: Pitt Katz | C371: Business Analytics & Operations (BAO) | D371: Analytics / Data Science | E371: 4 | F371: 9
A372: 48 | B372: Wake Forest SoB | C372: Analytics, IS, Marketing & OM (AISMOM) | D372: Analytics / Data Science | E372: 4 | F372: 12

Sheet 3. Faculty by Sub-Area
A1: Top 50 U.S. Business Schools — Research Sub-Area Faculty Detail
A2: 1 | B2: Wharton | C2: Accounting | D2: Financial Accounting | E2: 10 | F2: The Accounting Review; Journal of Accounting Research; Journal of Accounting & Economics
A3: 1 | B3: Wharton | C3: Accounting | D3: Managerial Accounting | E3: 7 | F3: Journal of Management Accounting Research; The Accounting Review
A4: 1 | B4: Wharton | C4: Accounting | D4: Auditing & Assurance | E4: 6 | F4: Auditing: A Journal of Practice & Theory; Contemporary Accounting Research
A5: 1 | B5: Wharton | C5: Accounting | D5: Tax Research | E5: 7 | F5: Journal of the American Taxation Association; National Tax Journal
A6: 1 | B6: Wharton | C6: Business Economics & Public Policy | D6: Industrial Organization | E6: 6 | F6: RAND Journal of Economics; Journal of Industrial Economics
A7: 1 | B7: Wharton | C7: Business Economics & Public Policy | D7: Public Policy & Regulation | E7: 6 | F7: Journal of Public Economics; American Economic Review
A8: 1 | B8: Wharton | C8: Business Economics & Public Policy | D8: Health Economics | E8: 5 | F8: Journal of Health Economics; American Economic Review
A9: 1 | B9: Wharton | C9: Business Economics & Public Policy | D9: Labor Economics | E9: 5 | F9: Journal of Labor Economics; Quarterly Journal of Economics
A10: 1 | B10: Wharton | C10: Finance | D10: Corporate Finance | E10: 10 | F10: Journal of Finance; Review of Financial Studies; Journal of Financial Economics
A11: 1 | B11: Wharton | C11: Finance | D11: Asset Pricing | E11: 10 | F11: Journal of Finance; Review of Financial Studies
A12: 1 | B12: Wharton | C12: Finance | D12: Financial Intermediation | E12: 8 | F12: Journal of Financial Intermediation; Journal of Financial Economics
A13: 1 | B13: Wharton | C13: Finance | D13: Behavioral Finance | E13: 7 | F13: Journal of Finance; Review of Financial Studies
... A1353: 50 | B1353: Miami Herbert | C1353: Marketing | D1353: Brand Management | E1353: 2 | F1353: Journal of Marketing Research; Journal of Marketing; Marketing Science; Journal of Consumer Research
E1354: =SUM(E4:E1275)

Sheet 4. Subject Area Analysis
A1: Subject Area Analysis
A2: Summary of research sub-areas across Top 50 U.S. Business Schools
A4: Total Sub-Areas | B4: 94 | C4: Total Departments | D4: 138 | E4: Total Faculty Entries | F4: 3524
A6: Sub-Areas Ranked by Total Faculty
A7: Rank | B7: Sub-Area | C7: Total Faculty | D7: # Schools | E7: # Depts | F7: Avg Faculty/School
A8: 1 | B8: Corporate Finance | C8: 177 | D8: 49 | E8: 5 | F8: 3.6
A9: 2 | B9: Asset Pricing | C9: 160 | D9: 49 | E9: 5 | F9: 3.3
A10: 3 | B10: Consumer Behavior | C10: 147 | D10: 49 | E10: 5 | F10: 3
A11: 4 | B11: Financial Accounting | C11: 137 | D11: 49 | E11: 9 | F11: 2.8
A12: 5 | B12: Banking & Financial Institutions | C12: 137 | D12: 47 | E12: 5 | F12: 2.9
A13: 6 | B13: International Finance | C13: 130 | D13: 48 | E13: 5 | F13: 2.7
A14: 7 | B14: Marketing Analytics | C14: 121 | D14: 47 | E14: 5 | F14: 2.6
A15: 8 | B15: Managerial Accounting | C15: 118 | D15: 49 | E15: 9 | F15: 2.4
A16: 9 | B16: Digital Marketing | C16: 118 | D16: 48 | E16: 5 | F16: 2.5
A17: 10 | B17: Supply Chain Management | C17: 116 | D17: 41 | E17: 31 | F17: 2.8
A18: 11 | B18: Strategic Management | C18: 111 | D18: 36 | E18: 23 | F18: 3.1
A19: 12 | B19: Auditing & Assurance | C19: 107 | D19: 49 | E19: 9 | F19: 2.2
... A101: 94 | B101: Commercial Real Estate | C101: 2 | D101: 1 | E101: 1 | F101: 2
A103: Departments Ranked by Total Faculty
A104: Rank | B104: Department | C104: Total Faculty | D104: # Schools | E104: # Sub-Areas | F104: Avg Faculty/School
A105: 1 | B105: Finance | C105: 568 | D105: 44 | E105: 6 | F105: 12.9
A106: 2 | B106: Marketing | C106: 472 | D106: 45 | E106: 8 | F106: 10.5
A107: 3 | B107: Accounting | C107: 342 | D107: 37 | E107: 5 | F107: 9.2
A108: 4 | B108: Management | C108: 158 | D108: 13 | E108: 6 | F108: 12.2
A109: 5 | B109: Economics | C109: 99 | D109: 11 | E109: 4 | F109: 9
A110: 6 | B110: Strategy | C110: 79 | D110: 7 | E110: 6 | F110: 11.3
A111: 7 | B111: Management & Organizations | C111: 77 | D111: 6 | E111: 4 | F111: 12.8
A112: 8 | B112: Operations Management | C112: 67 | D112: 9 | E112: 4 | F112: 7.4
A113: 9 | B113: Organizational Behavior | C113: 65 | D113: 6 | E113: 6 | F113: 10.8
A114: 10 | B114: Management & Organization | C114: 61 | D114: 5 | E114: 4 | F114: 12.2
A115: 11 | B115: Accountancy | C115: 45 | D115: 5 | E115: 4 | F115: 9
A116: 12 | B116: Business Economics & Public Policy | C116: 40 | D116: 3 | E116: 7 | F116: 13.3
... A242: 138 | B242: Strategy & Leadership | C242: 0 | D242: 1 | E242: 4 | F242: 0
A244: Schools Ranked by Faculty in Sub-Areas
A245: Rank | B245: School | C245: Total Faculty | D245: # Depts | E245: # Sub-Areas | F245: Avg Faculty/Dept
A246: 1 | B246: Wharton | C246: 246 | D246: 10 | E246: 40 | F246: 24.6
A247: 2 | B247: Harvard HBS | C247: 209 | D247: 10 | E247: 39 | F247: 20.9
A248: 3 | B248: Chicago Booth | C248: 144 | D248: 11 | E248: 32 | F248: 13.1
A249: 4 | B249: Kellogg | C249: 141 | D249: 7 | E249: 28 | F249: 20.1
A250: 5 | B250: Maryland Smith | C250: 135 | D250: 6 | E250: 24 | F250: 22.5
...

Sheet 5. Journals Reference
A1: Business School Research — Key Journals by Discipline
A2: Field / Discipline | B2: Top Journals Published In
A3: Accounting | B3: The Accounting Review; Journal of Accounting Research; Journal of Accounting & Economics; Review of Accounting Studies
A4: Finance | B4: Journal of Finance; Journal of Financial Economics; Review of Financial Studies; Journal of Financial & Quantitative Analysis
A5: Marketing | B5: Journal of Marketing; Journal of Marketing Research; Marketing Science; Journal of Consumer Research
A6: Strategy/Mgmt | B6: Strategic Management Journal; Academy of Management Review; Organization Science; Administrative Science Quarterly
A7: Operations | B7: Management Science; Operations Research; Manufacturing & Service Operations Mgmt; Production and Operations Management
A8: Economics/Policy | B8: American Economic Review; Journal of Political Economy; Quarterly Journal of Economics; RAND Journal of Economics
A9: OB/Negotiations | B9: Academy of Management Journal; Administrative Science Quarterly; Organization Science; Journal of Applied Psychology
A10: Info Systems | B10: MIS Quarterly; Information Systems Research; Management Science (IS); Journal of Management Information Systems
A11: Entrepreneurship | B11: Journal of Business Venturing; Entrepreneurship Theory & Practice; Strategic Entrepreneurship Journal
A12: Real Estate | B12: Journal of Real Estate Finance & Economics; Real Estate Economics; Journal of Urban Economics
A13: Statistics/ML | B13: Journal of the American Statistical Association; Annals of Statistics; Journal of Machine Learning Research
... A18: Macroeconomics | B18: American Economic Review; Journal of Political Economy; Journal of Monetary Economics; Review of Economic Studies

Sheet 6. Department Analysis
A1: DEPARTMENT ANALYSIS - Top 50 US Business Schools
A3: SECTION 1: What departments do most business schools have?
A5: Department Category | B5: # Schools with Dept | C5: % of 50 Schools | D5: Classification
A6: Finance | B6: 49 | C6: 0.98 | D6: Universal (Core)
A7: Marketing | B7: 49 | C7: 0.98 | D7: Universal (Core)
A8: Accounting | B8: 45 | C8: 0.9 | D8: Universal (Core)
A9: Operations & Information | B9: 45 | C9: 0.9 | D9: Universal (Core)
A10: OM + IS Combined | B10: 24 | C10: 0.48 | D10: Combined into single dept
A11: OM Only (no separate IS dept) | B11: 14 | C11: 0.28 | D11: OM without IS
A12: Both OM & IS Separate | B12: 10 | C12: 0.2 | D12: Separate OM and IS depts
A13: No OM or IS dept | B13: 2 | C13: 0.04 | D13: Neither identified
A14: Management & OB | B14: 44 | C14: 0.88 | D14: Universal (Core)
A15: Economics & Policy | B15: 26 | C15: 0.52 | D15: Common
A16: Strategy | B16: 24 | C16: 0.48 | D16: Common
A17: Other | B17: 12 | C17: 0.24 | D17: Occasional
... A20: Real Estate | B20: 2 | C20: 0.04 | D20: Rare / Specialized
A21: Statistics
A22: Health Care | B22: 1 | C22: 0.02 | D22: Rare / Specialized
A25: SECTION 2: What percentage of faculty in each department?
A26: Based on 16 schools with exact headcounts from faculty directories
A28: Department Category | B28: Present in (of 16) | C28: Total TT Faculty | D28: % of All Faculty | E28: Avg per School
A29: Management & OB | B29: 16/16 | C29: 359 | D29: 0.18419702 | E29: 22.4
A30: Finance | B30: 16/16 | C30: 346 | D30: 0.17752694 | E30: 21.6
A31: Operations & Information | B31: 15/16 | C31: 344 | D31: 0.17650077 | E31: 22.9
A32: Marketing | B32: 16/16 | C32: 260 | D32: 0.13340174 | E32: 16.2
A33: Economics & Policy | B33: 14/16 | C33: 239 | D33: 0.12262699 | E33: 17.1
A34: Accounting | B34: 16/16 | C34: 197 | D34: 0.10107748 | E34: 12.3
A35: Strategy | B35: 8/16 | C35: 87 | D35: 0.044638276 | E35: 10.9
A36: Other | B36: 3/16 | C36: 49 | D36: 0.025141098 | E36: 16.3
A37: Entrepreneurship | B37: 2/16 | C37: 30 | D37: 0.015392509 | E37: 15
A38: Legal & Ethics | B38: 1/16 | C38: 21 | D38: 0.010774756 | E38: 21
A39: Statistics | B39: 1/16 | C39: 14 | D39: 0.0071831709 | E39: 14
A40: Real Estate | B40: 1/16 | C40: 10 | D40: 0.0051308363 | E40: 10
A41: Health Care
A42: TOTAL | C42: 1949 | D42: 1
A45: SECTION 3: Exact Faculty Counts by School (16 schools with verified data)
A47: Rank | B47: School | C47: Total TT | D47: Accounting | E47: Economics & Policy | F47: Finance | G47: Management & OB | H47: Marketing | I47: Operations & Information | J47: Strategy | K47: Other
A48: 1 | B48: Wharton | C48: 246 | D48: 20 | E48: 19 | F48: 39 | G48: 57 | H48: 27 | I48: 53 | K48: 31
A49: 2 | B49: Harvard HBS | C49: 201 | D49: 17 | E49: 23 | F49: 24 | G49: 54 | H49: 15 | I49: 24 | J49: 18 | K49: 26
A50: 3 | B50: Chicago Booth | C50: 144 | D50: 21 | E50: 32 | F50: 25 | G50: 18 | H50: 17 | I50: 13 | K50: 18
...

Sheet 7. OM-IS-Analytics Mapping
A1: Rank | B1: School | C1: Operations Management Dept | D1: OM Faculty | E1: OM URL | F1: Information Systems Dept | G1: IS Faculty | H1: IS URL | I1: Analytics / Data Science Dept | J1: Analytics Faculty | K1: Analytics URL | L1: Structure | M1: Notes
A2: 1 | B2: Wharton | C2: OID (combined) | D2: 24 | E2: https://oid.wharton.upenn.edu/ | F2: OID (combined) | G2: 24 | H2: https://oid.wharton.upenn.edu/ | I2: Statistics & Data Science | J2: 25 | K2: https://statistics.wharton.upenn.edu/ | L2: Combined OM+IS+DS in OID; separate Stats dept | M2: OID covers OM, IS, Decision Processes
A3: 2 | B3: Harvard HBS | C3: Technology & Operations Mgmt (TOM) | D3: 17 | E3: https://www.hbs.edu/faculty/units/tom/Pages/faculty.aspx | F3: TOM (combined) | G3: 17 | I3: — | J3: — | L3: Combined | M3: TOM covers operations + technology/IS
A4: 3 | B4: Chicago Booth | C4: Operations Management | D4: 12 | E4: https://www.chicagobooth.edu/faculty/academic-areas/operations-management | F4: — | G4: — | I4: — | J4: — | L4: Separate OM only | M4: No dedicated IS or Analytics dept
A5: 4 | B5: Kellogg | C5: Operations | D5: 13 | E5: https://www.kellogg.northwestern.edu/faculty/academics/operations.aspx | F5: — | G5: — | I5: MEDS (includes decision science) | J5: 20 | K5: https://www.kellogg.northwestern.edu/faculty/academics/managerial-economics-decision-sciences.aspx | L5: Separate | M5: MEDS covers decision sciences and economics
A6: 5 | B6: MIT Sloan | C6: Operations Management | D6: 11 | E6: https://mitsloan.mit.edu/faculty/academic-groups/operations-management | F6: Information Technology | G6: 13 | H6: https://mitsloan.mit.edu/faculty/academic-groups/information-technology | I6: Operations Research & Statistics | J6: 14 | K6: https://mitsloan.mit.edu/faculty/academic-groups/operations-research-statistics | L6: All separate | M6: Three distinct groups
A7: 6 | B7: Stanford GSB | C7: OIT (combined) | D7: 11 | E7: https://www.gsb.stanford.edu/faculty-research/faculty/academic-areas/operations-information-technology | F7: OIT (combined) | G7: 11 | I7: — | J7: — | L7: Combined | M7: OIT covers operations + IS + technology
A8: 7 | B8: Columbia CBS | C8: DRO (combined) | D8: 17 | E8: https://business.columbia.edu/faculty/divisions/dro | F8: DRO (combined) | G8: 17 | I8: DRO (combined) | J8: 17 | L8: Combined | M8: DRO covers decision sciences, risk, operations
A9: 8 | B9: NYU Stern | C9: TOPS (combined) | D9: 17 | E9: https://www.stern.nyu.edu/experience-stern/about/departments-centers-initiatives/academic-departments/tops | F9: TOPS (combined) | G9: 17 | I9: TOPS (combined) | J9: 17 | L9: Combined | M9: TOPS covers technology, operations, statistics
A10: 9 | B10: Dartmouth Tuck | C10: Operations Mgmt & Mgmt Science | D10: 5 | E10: https://www.tuck.dartmouth.edu/faculty/academic-groups/operations-management | F10: — | G10: — | I10: — | J10: — | L10: Single OM dept
A11: 10 | B11: Yale SOM | C11: Operations | D11: 6 | E11: https://som.yale.edu/faculty-research/disciplines/operations | F11: — | G11: — | I11: — | J11: — | L11: Single OM area
A12: 11 | B12: Berkeley Haas | C12: OITM (combined) | D12: — | E12: https://haas.berkeley.edu/oitm/ | F12: OITM (combined) | G12: — | H12: https://haas.berkeley.edu/oitm/ | I12: — | J12: — | L12: Combined | M12: OITM = Operations & IT Management. MISSING from original spreadsheet
A13: 12 | B13: UVA Darden | C13: Technology & Operations Mgmt | D13: 9 | E13: https://www.darden.virginia.edu/faculty-research/academic-areas/technology-operations-management | F13: — | G13: — | I13: Data Analytics & Decision Sciences (DADS) | J13: 8 | K13: https://www.darden.virginia.edu/faculty-research/academic-areas/data-analytics-decision-sciences | L13: Separate | M13: Two distinct areas
A14: 13 | B14: Michigan Ross | C14: Technology & Operations | D14: 8 | E14: https://michiganross.umich.edu/faculty-research/areas-of-study/technology-operations | F14: T&O (combined) | G14: 8 | I14: — | J14: — | L14: Combined | M14: T&O covers operations + technology
A15: 14 | B15: Duke Fuqua | C15: Operations Management | D15: 6 | E15: https://areas.fuqua.duke.edu/operations-management/ | F15: — | G15: — | I15: Decision Sciences | J15: 5 | K15: https://areas.fuqua.duke.edu/decision-sciences/ | L15: Separate | M15: Two separate areas
A16: 15 | B16: Cornell Johnson | C16: OTIM (combined) | D16: 5 | E16: https://business.cornell.edu/faculty-research/areas/operations-technology-and-information-management/ | F16: OTIM (combined) | G16: 5 | I16: — | J16: — | L16: Combined | M16: OTIM covers operations, technology, IS
A17: 16 | B17: UT McCombs | C17: IROM (combined) | D17: 12 | E17: https://www.mccombs.utexas.edu/faculty-research/departments/irom/ | F17: IROM (combined) | G17: 12 | I17: IROM (combined) | J17: 12 | L17: Combined | M17: IROM covers IS, risk, operations
A18: 17 | B18: Emory Goizueta | C18: ISOM (combined) | D18: 8 | E18: https://goizueta.emory.edu/faculty/isom | F18: ISOM (combined) | G18: 8 | I18: — | J18: — | L18: Combined | M18: ISOM covers IS + OM
A19: 18 | B19: CMU Tepper | C19: Operations Management | D19: 7 | E19: https://www.cmu.edu/tepper/faculty-and-research/academic-areas/operations-management/ | F19: — | G19: — | I19: Operations Research | J19: 5 | K19: https://www.cmu.edu/tepper/faculty-and-research/academic-areas/operations-research/ | L19: Separate | M19: Two distinct areas
A20: 19 | B20: UCLA Anderson | C20: DOTM (combined) | D20: 5 | E20: https://www.anderson.ucla.edu/faculty-and-research/decisions-operations-and-technology-management | F20: DOTM (combined) | G20: 5 | I20: Behavioral Decision Making | J20: 5 | K20: https://www.anderson.ucla.edu/faculty-and-research/behavioral-decision-making | L20: Partial combined | M20: DOTM covers decisions + ops + tech; BDM is separate
A21: 20 | B21: Vanderbilt Owen | C21: Operations Management | D21: 5 | E21: https://business.vanderbilt.edu/our-school/faculty/operations/ | F21: — | G21: — | I21: — | J21: — | L21: Single OM dept
A22: 21 | B22: WashU Olin | C22: SCOT (combined) | D22: 8 | E22: https://olin.wustl.edu/faculty-research/academic-areas/supply-chain-operations-technology/ | F22: — | G22: — | I22: — | J22: — | L22: Combined | M22: SCOT = Supply Chain, Operations & Technology
A23: 22 | B23: Georgetown McDonough | C23: OPAN (combined) | D23: 7 | E23: https://msb.georgetown.edu/faculty-research/operations-analytics/ | F23: — | G23: — | I23: OPAN (combined) | J23: 7 | L23: Combined | M23: OPAN covers operations + analytics
A24: 23 | B24: Indiana Kelley | C24: ODT (combined) | D24: 5 | E24: https://kelley.iu.edu/faculty-research/departments/operations-decision-technologies/ | F24: ODT sub-area | G24: 5 | I24: ODT sub-area | J24: 5 | L24: Combined w/ sub-areas | M24: ODT has sub-groups: OM, IS, Analytics
A25: 24 | B25: UNC Kenan-Flagler | C25: Operations | D25: 5 | E25: https://www.kenan-flagler.unc.edu/faculty/academic-areas/operations/ | F25: — | G25: — | I25: — | J25: — | L25: Single OM area
A26: 25 | B26: Notre Dame Mendoza | C26: ITAO (combined) | D26: 10 | E26: https://mendoza.nd.edu/research-faculty/academic-departments/information-technology-analytics-operations/ | F26: ITAO (combined) | G26: 10 | I26: ITAO (combined) | J26: 10 | L26: Combined | M26: ITAO covers IT, Analytics, Operations
A27: 26 | B27: USC Marshall | C27: DSO (combined) | D27: 11 | E27: https://www.marshall.usc.edu/departments/data-sciences-and-operations | F27: DSO (combined) | G27: 11 | I27: DSO (combined) | J27: 11 | L27: Combined | M27: DSO covers data sciences + operations
A28: 27 | B28: Rice Jones | C28: Operations Management | D28: 7 | E28: https://business.rice.edu/faculty-research/research/operations-management | F28: — | G28: — | I28: — | J28: — | L28: Single OM dept
A29: 28 | B29: Minnesota Carlson | C29: Supply Chain & Operations | D29: 14 | E29: https://carlsonschool.umn.edu/departments/supply-chain-operations/ | F29: Information & Decision Sciences | G29: 16 | H29: https://carlsonschool.umn.edu/departments/information-decision-sciences/ | I29: — | J29: — | L29: Separate | M29: Two distinct departments
A30: 29 | B30: Ohio State Fisher | C30: Management Sciences | D30: 8 | E30: https://fisher.osu.edu/academic-departments/management-sciences | F30: Acct & MIS (combined w/ Acct) | G30: 7 | H30: https://fisher.osu.edu/academic-departments/amis/ | I30: — | J30: — | L30: Separate | M30: MIS is combined with Accounting
A31: 30 | B31: GT Scheller | C31: Operations Management | D31: 5 | E31: https://www.scheller.gatech.edu/academics-research/operations-management/ | F31: Information Technology Management | G31: 5 | H31: https://www.scheller.gatech.edu/academics-research/it-management/ | I31: — | J31: — | L31: Separate | M31: Two distinct departments
A32: 31 | B32: Penn State Smeal | C32: SCIS (combined) | D32: 6 | E32: https://www.smeal.psu.edu/scis | F32: SCIS (combined) | G32: 6 | I32: — | J32: — | L32: Combined | M32: SCIS = Supply Chain & Information Systems
A33: 32 | B33: Texas A&M Mays | C33: IOM (combined) | D33: 9 | E33: https://mays.tamu.edu/departments/information-and-operations-management/ | F33: IOM (combined) | G33: 9 | I33: — | J33: — | L33: Combined | M33: IOM covers IS + Operations
A34: 33 | B34: Purdue Daniels | C34: Quantitative Methods | D34: 9 | E34: https://business.purdue.edu/academics/quantitative-methods/ | F34: — | G34: — | I34: — | J34: — | L34: QM dept | M34: Also has Supply Chain & Ops Mgmt
A35: 34 | B35: ASU Carey | C35: Supply Chain Management | D35: 7 | E35: https://wpcarey.asu.edu/supply-chain-management-department | F35: Information Systems | G35: 6 | H35: https://wpcarey.asu.edu/information-systems-department | I35: — | J35: — | L35: Separate | M35: Two distinct departments
A36: 35 | B36: Wisconsin SoB | C36: Operations & Information Mgmt | D36: 6 | E36: https://business.wisc.edu/faculty-research/operations-information-management/ | F36: Acct & IS (combined w/ Acct) | G36: 5 | H36: https://business.wisc.edu/faculty-research/accounting-information-systems/ | I36: — | J36: — | L36: Mixed | M36: OIM combined; IS is with Accounting
A37: 36 | B37: Maryland Smith | C37: DO&IT (combined) | D37: 20 | E37: https://www.rhsmith.umd.edu/departments/decision-operations-information-technologies | F37: DO&IT (combined) | G37: 20 | I37: DO&IT (combined) | J37: 20 | L37: Combined | M37: DO&IT covers decision, ops, IS, tech
A38: 37 | B38: BU Questrom | C38: Operations & Technology Mgmt | D38: 9 | E38: https://www.bu.edu/questrom/faculty-research/academic-departments/operations-technology-management/ | F38: Information Systems | G38: 9 | H38: https://www.bu.edu/questrom/faculty-research/academic-departments/information-systems/ | I38: — | J38: — | L38: Separate | M38: Two distinct departments
A39: 38 | B39: UF Warrington | C39: ISOM (combined) | D39: 8 | E39: https://warrington.ufl.edu/information-systems-and-operations-management-department/ | F39: ISOM (combined) | G39: 8 | I39: — | J39: — | L39: Combined | M39: ISOM covers IS + Operations
A40: 39 | B40: SMU Cox | C40: ITOM (combined) | D40: 6 | E40: https://www.smu.edu/cox/academics/information-technology-and-operations-management-department | F40: ITOM (combined) | G40: 6 | I40: — | J40: — | L40: Combined | M40: ITOM covers IT + Operations
...

Sheet _Lookup
A1: ShortName | B1: FullName | C1: Rank | D1: TotalTT | E1: IS_OM_Status | F1: Analytics_Location
A2: Wharton | B2: University of Pennsylvania – Wharton School | C2: 1 | D2: 246 | E2: Combined (OID) | F2: Statistics & Data Science
A3: Harvard HBS | B3: Harvard University – Harvard Business School | C3: 2 | D3: 201 | E3: Combined (Technology & Operations Mgmt (TOM)) | F3: None
A4: Chicago Booth | B4: University of Chicago – Booth School of Business | C4: 3 | D4: 144 | E4: OM only | F4: None
A5: Kellogg | B5: Northwestern University – Kellogg School of Management | C5: 4 | D5: 141 | E5: OM only | F5: MEDS (includes decision science)
A6: MIT Sloan | B6: MIT – Sloan School of Management | C6: 5 | D6: 129 | E6: Separate OM & IS | F6: Operations Research & Statistics
A7: Stanford GSB | B7: Stanford University – Graduate School of Business | C7: 6 | D7: 122 | E7: Combined (OIT) | F7: None
A8: Columbia CBS | B8: Columbia University – Columbia Business School | C8: 7 | D8: 123 | E8: Combined (DRO) | F8: DRO
A9: NYU Stern | B9: New York University – Stern School of Business | C9: 8 | D9: 170 | E9: Combined (TOPS) | F9: TOPS
A10: Dartmouth Tuck | B10: Dartmouth College – Tuck School of Business | C10: 9 | D10: 45 | E10: OM only | F10: None
A11: Yale SOM | B11: Yale University – Yale School of Management | C11: 10 | D11: 110 | E11: OM only | F11: None
A12: Berkeley Haas | B12: UC Berkeley – Haas School of Business | C12: 11 | D12: 84 | E12: Combined (OITM) | F12: None
A13: UVA Darden | B13: University of Virginia – Darden School | C13: 12 | D13: 89 | E13: OM only | F13: Data Analytics & Decision Sciences (DADS)
... A22: WashU Olin | B22: Washington University – Olin Business School | C22: 21 | D22: 44 | E22: OM only | F22: None
A23: Georgetown MSOB | B23: Georgetown University – McDonough School | C23: 22 | D23: 79
A24: Indiana Kelley | B24: Indiana University – Kelley School of Business | C24: 23 | D24: 196 | E24: Combined (ODT) | F24: ODT sub-area
A25: UNC Kenan-Flagler | B25: UNC Chapel Hill – Kenan-Flagler Business School | C25: 24 | D25: 81 | E25: OM only | F25: None
A26: Notre Dame Mendoza | B26: University of Notre Dame – Mendoza College | C26: 25 | D26: 98 | E26: Combined (ITAO) | F26: ITAO
A27: USC Marshall | B27: USC – Marshall School of Business | C27: 26 | D27: 136 | E27: Combined (DSO) | F27: DSO
A28: Rice Jones | B28: Rice University – Jones Graduate School | C28: 27 | D28: 60 | E28: OM only | F28: None
A29: Minnesota Carlson | B29: University of Minnesota – Carlson School of Mgmt | C29: 28 | D29: 86 | E29: Separate OM & IS | F29: None
A30: Ohio State Fisher | B30: Ohio State University – Fisher College of Business | C30: 29 | D30: 49 | E30: Combined (Management Sciences) | F30: None
A31: GT Scheller | B31: Georgia Tech – Scheller College of Business | C31: 30 | D31: 61 | E31: Separate OM & IS | F31: None
A32: Penn State Smeal | B32: Penn State – Smeal College of Business | C32: 31 | D32: 121 | E32: Combined (SCIS) | F32: None
A33: Texas A&M Mays | B33: Texas A&M – Mays Business School | C33: 32 | D33: 99 | E33: Combined (IOM) | F33: None
A34: Purdue Krannert | B34: Purdue University – Krannert School of Management | C34: 33 | D34: 103
A35: ASU Carey | B35: Arizona State University – Carey School of Business | C35: 34 | D35: 44 | E35: Separate OM & IS | F35: None
A36: Wisconsin SoB | B36: University of Wisconsin – School of Business | C36: 35 | D36: 92 | E36: Combined (Operations & Information Mgmt) | F36: None
A37: Maryland Smith | B37: University of Maryland – Smith School of Business | C37: 36 | D37: 89 | E37: Combined (DO&IT) | F37: DO&IT
A38: BU Questrom | B38: Boston University – Questrom School of Business | C38: 37 | D38: 86 | E38: Separate OM & IS | F38: None
A39: UF Warrington | B39: University of Florida – Warrington College | C39: 38 | D39: 50 | E39: Combined (ISOM) | F39: None
A40: SMU Cox | B40: Southern Methodist Univ. – Cox School of Business | C40: 39 | D40: 59 | E40: Combined (ITOM) | F40: None
A41: UW Foster | B41: University of Washington – Foster School of Business | C41: 40 | D41: 74 | E41: Combined (ISOM) | F41: None
A42: Pitt Katz | B42: University of Pittsburgh – Katz Graduate School | C42: 41 | D42: 59 | E42: Separate OM & IS | F42: BAO includes analytics
A43: NEU DAmore-McKim | B43: Northeastern – DAmore-McKim School of Business | C43: 42 | D43: 46
A44: Tulane Freeman | B44: Tulane University – Freeman School of Business | C44: 43 | D44: 57 | E44: — | F44: None
A45: Iowa Tippie | B45: University of Iowa – Tippie College of Business | C45: 44 | D45: 43 | E45: — | F45: Business Analytics
A46: GWU GWSB | B46: George Washington Univ. – School of Business | C46: 45 | D46: 83 | E46: Separate OM & IS | F46: None
A47: BYU Marriott | B47: Brigham Young Univ. – Marriott School of Business | C47: 46 | D47: 123 | E47: Separate OM & IS | F47: None
A48: Rochester Simon | B48: Univ. of Rochester – Simon Business School | C48: 47 | D48: 43 | E48: OM only | F48: None
...

Sheet _DeptLookup
A1: Key | B1: School | C1: DeptName | D1: Faculty | E1: URL
A2: Wharton|1 | B2: Wharton | C2: Management | D2: 47 | E2: https://mgmt.wharton.upenn.edu/faculty/
A3: Wharton|2 | B3: Wharton | C3: Finance | D3: 39 | E3: https://fnce.wharton.upenn.edu/faculty/
A4: Wharton|3 | B4: Wharton | C4: Operations, Information and Decisions (OID) | D4: 30 | E4: https://oid.wharton.upenn.edu/
A5: Wharton|4 | B5: Wharton | C5: Marketing | D5: 27 | E5: https://marketing.wharton.upenn.edu/faculty/
A6: Wharton|5 | B6: Wharton | C6: Statistics and Data Science | D6: 23 | E6: https://statistics.wharton.upenn.edu/
A7: Wharton|6 | B7: Wharton | C7: Accounting | D7: 20 | E7: https://accounting.wharton.upenn.edu/faculty/
A8: Wharton|7 | B8: Wharton | C8: Legal Studies & Business Ethics | D8: 20 | E8: https://lgst.wharton.upenn.edu/faculty/
A9: Wharton|8 | B9: Wharton | C9: Business Economics & Public Policy | D9: 19 | E9: https://bepp.wharton.upenn.edu/faculty/
A10: Wharton|9 | B10: Wharton | C10: Health Care Management | D10: 10 | E10: https://hcmg.wharton.upenn.edu/faculty/
A11: Wharton|10 | B11: Wharton | C11: Real Estate | D11: 10 | E11: https://real-estate.wharton.upenn.edu/faculty/
A12: Harvard HBS|1 | B12: Harvard HBS | C12: Finance | D12: 27 | E12: https://www.hbs.edu/faculty/units/finance/Pages/faculty.aspx
A13: Harvard HBS|2 | B13: Harvard HBS | C13: Entrepreneurial Management | D13: 26 | E13: https://www.hbs.edu/faculty/units/em/Pages/faculty.aspx
... A164: Indiana Kelley|1 | B164: Indiana Kelley | C164: Operations & Decision Technologies (ODT) | D164: 37 | E164: https://kelley.iu.edu/faculty-research/departments/operations-decision-technologies/
A165: Indiana Kelley|2 | B165: Indiana Kelley | C165: Operations & Decision Technologies (ODT) | D165: 37
A166: Indiana Kelley|3 | B166: Indiana Kelley | C166: Management & Entrepreneurship | D166: 34 | E166: https://kelley.iu.edu/faculty-research/departments/
A167: Indiana Kelley|4 | B167: Indiana Kelley | C167: Accounting | D167: 31 | E167: https://kelley.iu.edu/faculty-research/departments/
A168: Indiana Kelley|5 | B168: Indiana Kelley | C168: Finance | D168: 30 | E168: https://kelley.iu.edu/faculty-research/departments/
A169: Indiana Kelley|6 | B169: Indiana Kelley | C169: Marketing | D169: 25 | E169: https://kelley.iu.edu/faculty-research/departments/
A170: Indiana Kelley|7 | B170: Indiana Kelley | C170: Business Economics & Public Policy | D170: 18 | E170: https://kelley.iu.edu/faculty-research/departments/
A171: Indiana Kelley|8 | B171: Indiana Kelley | C171: Business Law & Ethics | D171: 16 | E171: https://kelley.iu.edu/faculty-research/departments/
A172: UNC Kenan-Flagler|1 | B172: UNC Kenan-Flagler | C172: Finance | D172: 20 | E172: https://www.kenan-flagler.unc.edu/faculty/academic-areas/finance/
A173: UNC Kenan-Flagler|2 | B173: UNC Kenan-Flagler | C173: Accounting | D173: 16 | E173: https://www.kenan-flagler.unc.edu/faculty/academic-areas/accounting/
A174: UNC Kenan-Flagler|3 | B174: UNC Kenan-Flagler | C174: Marketing | D174: 15 | E174: https://www.kenan-flagler.unc.edu/faculty/academic-areas/marketing/
A175: UNC Kenan-Flagler|4 | B175: UNC Kenan-Flagler | C175: Operations | D175: 14 | E175: https://www.kenan-flagler.unc.edu/faculty/academic-areas/operations/
A176: UNC Kenan-Flagler|5 | B176: UNC Kenan-Flagler | C176: Strategy & Entrepreneurship | D176: 13 | E176: https://www.kenan-flagler.unc.edu/faculty/academic-areas/strategy-and-entrepreneurship/
A177: UNC Kenan-Flagler|6 | B177: UNC Kenan-Flagler | C177: Organizational Behavior | D177: 10 | E177: https://www.kenan-flagler.unc.edu/faculty/academic-areas/organizational-behavior/
... A279: Pitt Katz|3 | B279: Pitt Katz | C279: Business Analytics and Operations | D279: 9 | E279: https://www.business.pitt.edu/academics/business-analytics-operations/
A280: Pitt Katz|4 | B280: Pitt Katz | C280: Business Analytics & Operations (BAO) | D280: 9
A281: Pitt Katz|5 | B281: Pitt Katz | C281: Strategic Management | D281: 8 | E281: https://business.pitt.edu/academics/
A282: Pitt Katz|6 | B282: Pitt Katz | C282: Marketing | D282: 7 | E282: https://business.pitt.edu/academics/
A283: Pitt Katz|7 | B283: Pitt Katz | C283: Organizational Behavior & Human Resources | D283: 7 | E283: https://business.pitt.edu/academics/
A284: Pitt Katz|8 | B284: Pitt Katz | C284: Information Systems and Technology Management | D284: 6 | E284: https://www.business.pitt.edu/academics/information-systems-technology-management/
A285: NEU DAmore-McKim|1 | B285: NEU DAmore-McKim | C285: Finance | D285: 8 | E285: https://damore-mckim.northeastern.edu/academic-groups/
A286: NEU DAmore-McKim|2 | B286: NEU DAmore-McKim | C286: Management & Organizational Development | D286: 7 | E286: https://damore-mckim.northeastern.edu/academic-groups/
A287: NEU DAmore-McKim|3 | B287: NEU DAmore-McKim | C287: Supply Chain & Information Management (Academic Group) | D287: 7 | E287: https://damore-mckim.northeastern.edu/supply-chain/
A288: NEU DAmore-McKim|4 | B288: NEU DAmore-McKim | C288: Accounting | D288: 6 | E288: https://damore-mckim.northeastern.edu/academic-groups/
A289: NEU DAmore-McKim|5 | B289: NEU DAmore-McKim | C289: Economics | D289: 6 | E289: https://damore-mckim.northeastern.edu/academic-groups/
A290: NEU DAmore-McKim|6 | B290: NEU DAmore-McKim | C290: Supply Chain & Information Management (Academic Group) | D290: 6 | E290: https://damore-mckim.northeastern.edu/supply-chain/
A291: NEU DAmore-McKim|7 | B291: NEU DAmore-McKim | C291: Marketing | D291: 6 | E291: https://damore-mckim.northeastern.edu/academic-groups/
...

Sheet 8. Verification Summary
A1: School | B1: Department | C1: v13 Count | D1: Verified Count | E1: Status | F1: Difference
A2: BU Questrom | B2: Accounting | C2: 9 | D2: 11 | E2: Close (±1-2) | F2: 2
A3: BU Questrom | B3: Finance | C3: 13 | D3: 17 | E3: Discrepancy | F3: 4
A4: BU Questrom | B4: Information Systems | C4: 12 | D4: 15 | E4: Discrepancy | F4: 3
A5: BU Questrom | B5: Management & Organizations | C5: 11 | D5: 11 | E5: Confirmed | F5: 0
A6: BU Questrom | B6: Marketing | C6: 14 | D6: 17 | E6: Discrepancy | F6: 3
A7: BU Questrom | B7: Markets, Public Policy, and Law | C7: 10 | D7: 12 | E7: Close (±1-2) | F7: 2
A8: BU Questrom | B8: Operations and Technology Management | C8: 6 | D8: 7 | E8: Close (±1-2) | F8: 1
A9: BU Questrom | B9: Public Policy & Law | C9: 3 | E9: Flag | F9: -3
A10: BU Questrom | B10: Strategy and Innovation | C10: 8 | D10: 11 | E10: Discrepancy | F10: 3
A11: BYU Marriott | B11: Experience Design and Management | C11: 8 | D11: 8 | E11: Confirmed | F11: 0
A12: BYU Marriott | B12: Finance | C12: 20 | D12: 21 | E12: Close (±1-2) | F12: 1
A13: BYU Marriott | B13: Information Systems | C13: 15 | D13: 15 | E13: Confirmed | F13: 0
A14: BYU Marriott | B14: Management | C14: 26 | D14: 27 | E14: Close (±1-2) | F14: 1
A15: BYU Marriott | B15: Marketing and Global Supply Chain | C15: 21 | D15: 20 | E15: Close (±1-2) | F15: -1
A16: BYU Marriott | B16: Romney Institute of Public Service and Ethics | C16: 11 | D16: 12 | E16: Close (±1-2) | F16: 1
A17: BYU Marriott | B17: School of Accountancy | C17: 22 | D17: 23 | E17: Close (±1-2) | F17: 1
A18: Berkeley Haas | B18: Accounting | C18: 9 | D18: 9 | E18: Confirmed | F18: 0
A19: Berkeley Haas | B19: Business & Public Policy | C19: 13 | D19: 12 | E19: Close (±1-2) | F19: -1
A20: Berkeley Haas | B20: Economic Analysis & Policy | C20: 19 | D20: 19 | E20: Confirmed | F20: 0
A21: Berkeley Haas | B21: Finance | C21: 12 | D21: 12 | E21: Confirmed | F21: 0
... A344: Yale SOM | B344: Organizational Behavior | C344: 13 | D344: 13 | E344: Confirmed | F344: 0

Sheet 9. Key Findings
A1: Business School Faculty Composition Analysis - Key Findings
A3: RANKINGS CROSS-REFERENCED:
A4: US News 2025 MBA, US News 2026 Undergraduate Business,
A5: Bloomberg Businessweek 2025-26 MBA, Financial Times 2026 MBA,
A6: Poets & Quants Composite. Schools included if ranked ~top 50 in any major ranking.
A8: Dataset: 49 Top US Business Schools (Iowa Tippie & Arkansas Walton excluded — servers unavailable at scrape time)
A9: Total tenure-track faculty counted: 4903
A10: Average TT faculty per school: 100
A12: MOST COMMON DEPARTMENTS (ordered by prevalence):
A13: Accounting: 49/49 schools (100%) — avg 13.6 faculty (14.1% of total)
A14: Finance: 49/49 schools (100%) — avg 18.4 faculty (18.7% of total)
A15: Marketing: 49/49 schools (100%) — avg 14.4 faculty (15.2% of total)
... A39: - Note: Pittsburgh Katz dept breakdown estimated (titles say 'Professor of Business Administration')

Sheet Changelog (v12→v13)
A1: Changelog: v12 → v13
A2: Reconciliation of BSchool_Faculty_Analysis_v2 verification data into Top50_BSchools spreadsheet
A4: Summary of Changes
A5: Faculty counts updated | B5: 207
A6: School totals updated | B6: 31
A7: _DeptLookup entries updated | B7: 190
A8: Departments matched | B8: 242
A9: Unmatched departments (uploaded file) | B9: 101
A10: New sheets added | B10: 8. Verification Summary, 9. Key Findings
A12: Detailed Faculty Count Changes
A13: School | B13: Department | C13: Old Count | D13: New Count | E13: Diff | F13: Verification Status | G13: Notes
A14: BU Questrom | B14: Accounting | C14: 9 | D14: 11 | E14: 2 | F14: Close (±1-2) | G14: File: 9, Verified: 11 (diff: +2)
A15: BU Questrom | B15: Finance | C15: 12 | D15: 17 | E15: 5 | F15: Discrepancy | G15: File: 13, Verified: 17 (diff: +4). Exact match
A16: BU Questrom | B16: Information Systems | C16: 9 | D16: 15 | E16: 6 | F16: Discrepancy | G16: File: 12, Verified: 15 (diff: +3). Exact match
A17: BU Questrom | B17: Management & Organizations | C17: 10 | D17: 11 | E17: 1 | F17: Confirmed | G17: Exact match with verified count
A18: BU Questrom | B18: Marketing | C18: 9 | D18: 17 | E18: 8 | F18: Discrepancy | G18: File: 14, Verified: 17 (diff: +3). Exact match
A19: BU Questrom | B19: Markets, Public Policy, and Law | C19: 9 | D19: 12 | E19: 3 | F19: Close (±1-2) | G19: File: 10, Verified: 12 (under by 2). DISCREPANCY: Claimed 10, verified 12 TT. TT faculty: Sarah Armi
A20: BU Questrom | B20: Operations and Technology Management | C20: 9 | D20: 7 | E20: -2 | F20: Close (±1-2) | G20: File: 6, Verified: 7 (under by 1). DISCREPANCY: Claimed 6, verified 7 TT. TT faculty: Anita Carson (
A21: BU Questrom | B21: Public Policy & Law | C21: 9 | D21: N/A | E21: 0 | F21: Flag | G21: FLAG: This appears to be a duplicate/overlap with 'Markets, Public Policy, and Law' above. BU Questr
A22: BU Questrom | B22: Strategy and Innovation | C22: 9 | D22: 11 | E22: 2 | F22: Discrepancy | G22: File: 8, Verified: 11 (under by 3). DISCREPANCY: Claimed 8, verified 11 TT. TT faculty: Luis Ballest
A23: BYU Marriott | B23: Finance | C23: 9 | D23: 21 | E23: 12 | F23: Close (±1-2) | G23: File: 20, Verified: 21 (under by 1). 21 TT faculty: Aiello, Argyle, Boyer, Brau J, Carpenter, Diethe
A24: BYU Marriott | B24: Information Systems | C24: 7 | D24: 15 | E24: 8 | F24: Confirmed | G24: Exact match. 15 TT faculty: Anderson B, Anderson G, Gaskin, Giboney, Jenkins, Keith, Liddle, Meservy
A25: BYU Marriott | B25: Management | C25: 8 | D25: 27 | E25: 19 | F25: Close (±1-2) | G25: File: 26, Verified: 27 (under by 1). 27 TT faculty: Allen R, Bednar J, Benson, Bingham, Bryce, Carlo
A26: BYU Marriott | B26: Marketing and Global Supply Chain | C26: 8 | D26: 20 | E26: 12 | F26: Close (±1-2) | G26: File: 21, Verified: 20 (over by 1). 20 TT faculty: Allen BJ, Bale C, Bale M, Billeter, Blair, Brau B
A27: BYU Marriott | B27: School of Accountancy | C27: 7 | D27: 23 | E27: 16 | F27: Close (±1-2) | G27: File: 22, Verified: 23 (under by 1). 23 TT faculty: Allen A, Barrick, Donahoo, Drake, Dyer T, Fox Z,
A28: Berkeley Haas | B28: Accounting | C28: 13 | D28: 9 | E28: -4 | F28: Confirmed | G28: Exact match with verified count
A29: Berkeley Haas | B29: Business & Public Policy | C29: 13 | D29: 12 | E29: -1 | F29: Close (±1-2) | G29: File: 13, Verified: 12 (diff: -1)
A30: Berkeley Haas | B30: Finance | C30: 16 | D30: 12 | E30: -4 | F30: Confirmed | G30: Exact match with verified count
A31: Berkeley Haas | B31: Management of Organizations | C31: 14 | D31: 11 | E31: -3 | F31: Confirmed | G31: Exact match with verified count
A32: Berkeley Haas | B32: Marketing | C32: 15 | D32: 13 | E32: -2 | F32: Close (±1-2) | G32: File: 12, Verified: 13 (diff: +1)
A33: CMU Tepper | B33: Accounting | C33: 6 | D33: 5 | E33: -1 | F33: Confirmed | G33: Exact match with verified count
... A220: Yale SOM | B220: Organizational Behavior | C220: 5 | D220: 13 | E220: 8 | F220: Confirmed | G220: Exact match with verified count
A222: School Total Changes
A223: School | C223: Old Total | D223: New Total | E223: Diff
A224: BU Questrom | C224: 76 | D224: 86 | E224: 10
A225: BYU Marriott | C225: 62 | D225: 123 | E225: 61
A226: CMU Tepper | C226: 46 | D226: 82 | E226: 36
A227: Dartmouth Tuck | C227: 34 | D227: 55 | E227: 21
A228: Duke Fuqua | C228: 47 | D228: 95 | E228: 48
A229: Emory Goizueta | C229: 41 | D229: 45 | E229: 4
...

Sheet Changelog (v13→v14)
A1: Category | B1: School | C1: Department | D1: Old Value | E1: New Value | F1: Difference | G1: Status
A2: Dept Faculty | B2: Cornell Johnson | C2: Strategy & Business Economics | D2: 6 | E2: 25 | F2: 19 | G2: Confirmed
A3: Dept Faculty | B3: Dartmouth Tuck | C3: Strategic Management | D3: 7 | E3: 5 | F3: -2 | G3: Confirmed
A4: Dept Faculty | B4: Duke Fuqua | C4: Management | D4: 14 | E4: 6 | F4: -8 | G4: Confirmed
A5: Dept Faculty | B5: Purdue Krannert | C5: Management | D5: 10 | E5: 11 | F5: 1 | G5: Discrepancy
A6: Dept Faculty | B6: Purdue Krannert | C6: Quantitative Methods | D6: 9 | E6: 16 | F6: 7 | G6: Discrepancy
A7: Dept Faculty | B7: Rice Jones | C7: Management | D7: 7 | E7: 6 | F7: -1 | G7: Confirmed
A8: Dept Faculty | B8: Rice Jones | C8: Strategic Management | D8: 12 | E8: 6 | F8: -6 | G8: Confirmed
A9: Dept Faculty | B9: UCLA Anderson | C9: Management & Organizations | D9: 14 | E9: 4 | F9: -10 | G9: Confirmed
A10: Dept Faculty | B10: UW Foster | C10: Marketing & International Business | D10: 17 | E10: 18 | F10: 1 | G10: Close (±1-2)
A11: School Total | B11: Cornell Johnson | C11: (all depts) | D11: 145 | E11: 151 | F11: 6
A12: School Total | B12: Dartmouth Tuck | C12: (all depts) | D12: 55 | E12: 45 | F12: -10
A13: School Total | B13: Duke Fuqua | C13: (all depts) | D13: 95 | E13: 96 | F13: 1
A14: School Total | B14: Purdue Krannert | C14: (all depts) | D14: 104 | E14: 103 | F14: -1
A15: School Total | B15: Rice Jones | C15: (all depts) | D15: 73 | E15: 60 | F15: -13
A16: School Total | B16: UCLA Anderson | C16: (all depts) | D16: 68 | E16: 60 | F16: -8
A17: School Total | B17: UW Foster | C17: (all depts) | D17: 95 | E17: 74 | F17: -21
